Workbook

Sheet Q1
A1: product | B1: jan | C1: feb | D1: mar | E1: total | G1: que | H1: dynamic ch. | J1: ans
A2: coffee | B2: 322 | C2: 554 | D2: 299 | E2: =SUM(B2:D2) -> 1175
A3: candy | B3: 655 | C3: 576 | D3: 687 | E3: =SUM(B3:D3) -> 1918 | G3: find total of sugar | H3: total | I3: product
A4: chocalate | B4: 207 | C4: 155 | D4: 152 | E4: =SUM(B4:D4) -> 514 | I4: candy | J4: =DGET(A1:E11,H3,I3:I4) -> 1918
A5: sugar | B5: 692 | C5: 219 | D5: 646 | E5: =SUM(B5:D5) -> 1557
A6: milk powder | B6: 207 | C6: 822 | D6: 395 | E6: =SUM(B6:D6) -> 1424
A7: biscuits | B7: 759 | C7: 652 | D7: 447 | E7: =SUM(B7:D7) -> 1858
A8: cold drinks | B8: 447 | C8: 623 | D8: 579 | E8: =SUM(B8:D8) -> 1649
A9: energy drinks | B9: 195 | C9: 554 | D9: 727 | E9: =SUM(B9:D9) -> 1476
A10: fruits juice | B10: 211 | C10: 850 | D10: 799 | E10: =SUM(B10:D10) -> 1860
A11: total | B11: =SUM(B2:B10) -> 3695 | C11: =SUM(C2:C10) -> 5005 | D11: =SUM(D2:D10) -> 4731 | E11: =SUM(E2:E10) -> 13431

Sheet Q2
A1: product | B1: jan | C1: feb | D1: mar | E1: total
A2: coffee | B2: 514 | C2: 799 | D2: 394 | E2: =SUM(B2:D2) -> 1707
A3: candy | B3: 934 | C3: 242 | D3: 256 | E3: =SUM(B3:D3) -> 1432
A4: chocalate | B4: 327 | C4: 526 | D4: 291 | E4: =SUM(B4:D4) -> 1144
A5: sugar | B5: 644 | C5: 525 | D5: 867 | E5: =SUM(B5:D5) -> 2036
A6: milk powder | B6: 975 | C6: 537 | D6: 210 | E6: =SUM(B6:D6) -> 1722
A7: biscuits | B7: 306 | C7: 694 | D7: 336 | E7: =SUM(B7:D7) -> 1336
A8: cold drinks | B8: 811 | C8: 181 | D8: 610 | E8: =SUM(B8:D8) -> 1602
A9: energy drinks | B9: 253 | C9: 964 | D9: 637 | E9: =SUM(B9:D9) -> 1854
A10: fruits juice | B10: 936 | C10: 986 | D10: 252 | E10: =SUM(B10:D10) -> 2174
A11: total | B11: =SUM(B2:B10) -> 5700 | C11: =SUM(C2:C10) -> 5454 | D11: =SUM(D2:D10) -> 3853 | E11: =SUM(E2:E10) -> 15007

Sheet Q3
A1: product | B1: jan | C1: feb | D1: mar | E1: total
A2: coffee | B2: 870 | C2: 207 | D2: 117 | E2: =SUM(B2:D2) -> 1194
A3: candy | B3: 279 | C3: 158 | D3: 253 | E3: =SUM(B3:D3) -> 690
A4: chocalate | B4: 993 | C4: 322 | D4: 345 | E4: =SUM(B4:D4) -> 1660
A5: sugar | B5: 608 | C5: 247 | D5: 602 | E5: =SUM(B5:D5) -> 1457
A6: milk powder | B6: 690 | C6: 651 | D6: 728 | E6: =SUM(B6:D6) -> 2069
A7: biscuits | B7: 670 | C7: 590 | D7: 343 | E7: =SUM(B7:D7) -> 1603
A8: cold drinks | B8: 529 | C8: 551 | D8: 839 | E8: =SUM(B8:D8) -> 1919
A9: energy drinks | B9: 997 | C9: 706 | D9: 860 | E9: =SUM(B9:D9) -> 2563
A10: fruits juice | B10: 621 | C10: 523 | D10: 780 | E10: =SUM(B10:D10) -> 1924
A11: total | B11: =SUM(B2:B10) -> 6257 | C11: =SUM(C2:C10) -> 3955 | D11: =SUM(D2:D10) -> 4867 | E11: =SUM(E2:E10) -> 15079

Sheet SUM
B1: jan | C1: feb | D1: mar | E1: total
B2: ='Q1'!$B$2 -> 322 | C2: ='Q1'!$C$2 -> 554 | D2: ='Q1'!$D$2 -> 299 | E2: ='Q1'!$E$2 -> 1175
B3: ='Q2'!$B$2 -> 514 | C3: ='Q2'!$C$2 -> 799 | D3: ='Q2'!$D$2 -> 394 | E3: ='Q2'!$E$2 -> 1707
B4: ='Q3'!$B$2 -> 870 | C4: ='Q3'!$C$2 -> 207 | D4: ='Q3'!$D$2 -> 117 | E4: ='Q3'!$E$2 -> 1194
A5: coffee | B5: =SUM(B2:B4) -> 1706 | C5: =SUM(C2:C4) -> 1560 | D5: =SUM(D2:D4) -> 810 | E5: =SUM(E2:E4) -> 4076
B6: ='Q1'!$B$3 -> 655 | C6: ='Q1'!$C$3 -> 576 | D6: ='Q1'!$D$3 -> 687 | E6: ='Q1'!$E$3 -> 1918
B7: ='Q2'!$B$3 -> 934 | C7: ='Q2'!$C$3 -> 242 | D7: ='Q2'!$D$3 -> 256 | E7: ='Q2'!$E$3 -> 1432
B8: ='Q3'!$B$3 -> 279 | C8: ='Q3'!$C$3 -> 158 | D8: ='Q3'!$D$3 -> 253 | E8: ='Q3'!$E$3 -> 690
A9: candy | B9: =SUM(B6:B8) -> 1868 | C9: =SUM(C6:C8) -> 976 | D9: =SUM(D6:D8) -> 1196 | E9: =SUM(E6:E8) -> 4040
B10: ='Q1'!$B$4 -> 207 | C10: ='Q1'!$C$4 -> 155 | D10: ='Q1'!$D$4 -> 152 | E10: ='Q1'!$E$4 -> 514
B11: ='Q2'!$B$4 -> 327 | C11: ='Q2'!$C$4 -> 526 | D11: ='Q2'!$D$4 -> 291 | E11: ='Q2'!$E$4 -> 1144
B12: ='Q3'!$B$4 -> 993 | C12: ='Q3'!$C$4 -> 322 | D12: ='Q3'!$D$4 -> 345 | E12: ='Q3'!$E$4 -> 1660
A13: chocalate | B13: =SUM(B10:B12) -> 1527 | C13: =SUM(C10:C12) -> 1003 | D13: =SUM(D10:D12) -> 788 | E13: =SUM(E10:E12) -> 3318
B14: ='Q1'!$B$5 -> 692 | C14: ='Q1'!$C$5 -> 219 | D14: ='Q1'!$D$5 -> 646 | E14: ='Q1'!$E$5 -> 1557
B15: ='Q2'!$B$5 -> 644 | C15: ='Q2'!$C$5 -> 525 | D15: ='Q2'!$D$5 -> 867 | E15: ='Q2'!$E$5 -> 2036
B16: ='Q3'!$B$5 -> 608 | C16: ='Q3'!$C$5 -> 247 | D16: ='Q3'!$D$5 -> 602 | E16: ='Q3'!$E$5 -> 1457
A17: sugar | B17: =SUM(B14:B16) -> 1944 | C17: =SUM(C14:C16) -> 991 | D17: =SUM(D14:D16) -> 2115 | E17: =SUM(E14:E16) -> 5050
B18: ='Q1'!$B$6 -> 207 | C18: ='Q1'!$C$6 -> 822 | D18: ='Q1'!$D$6 -> 395 | E18: ='Q1'!$E$6 -> 1424
B19: ='Q2'!$B$6 -> 975 | C19: ='Q2'!$C$6 -> 537 | D19: ='Q2'!$D$6 -> 210 | E19: ='Q2'!$E$6 -> 1722
B20: ='Q3'!$B$6 -> 690 | C20: ='Q3'!$C$6 -> 651 | D20: ='Q3'!$D$6 -> 728 | E20: ='Q3'!$E$6 -> 2069
A21: milk powder | B21: =SUM(B18:B20) -> 1872 | C21: =SUM(C18:C20) -> 2010 | D21: =SUM(D18:D20) -> 1333 | E21: =SUM(E18:E20) -> 5215
B22: ='Q1'!$B$7 -> 759 | C22: ='Q1'!$C$7 -> 652 | D22: ='Q1'!$D$7 -> 447 | E22: ='Q1'!$E$7 -> 1858
B23: ='Q2'!$B$7 -> 306 | C23: ='Q2'!$C$7 -> 694 | D23: ='Q2'!$D$7 -> 336 | E23: ='Q2'!$E$7 -> 1336
B24: ='Q3'!$B$7 -> 670 | C24: ='Q3'!$C$7 -> 590 | D24: ='Q3'!$D$7 -> 343 | E24: ='Q3'!$E$7 -> 1603
A25: biscuits | B25: =SUM(B22:B24) -> 1735 | C25: =SUM(C22:C24) -> 1936 | D25: =SUM(D22:D24) -> 1126 | E25: =SUM(E22:E24) -> 4797
B26: ='Q1'!$B$8 -> 447 | C26: ='Q1'!$C$8 -> 623 | D26: ='Q1'!$D$8 -> 579 | E26: ='Q1'!$E$8 -> 1649
B27: ='Q2'!$B$8 -> 811 | C27: ='Q2'!$C$8 -> 181 | D27: ='Q2'!$D$8 -> 610 | E27: ='Q2'!$E$8 -> 1602
B28: ='Q3'!$B$8 -> 529 | C28: ='Q3'!$C$8 -> 551 | D28: ='Q3'!$D$8 -> 839 | E28: ='Q3'!$E$8 -> 1919
A29: cold drinks | B29: =SUM(B26:B28) -> 1787 | C29: =SUM(C26:C28) -> 1355 | D29: =SUM(D26:D28) -> 2028 | E29: =SUM(E26:E28) -> 5170
B30: ='Q1'!$B$9 -> 195 | C30: ='Q1'!$C$9 -> 554 | D30: ='Q1'!$D$9 -> 727 | E30: ='Q1'!$E$9 -> 1476
B31: ='Q2'!$B$9 -> 253 | C31: ='Q2'!$C$9 -> 964 | D31: ='Q2'!$D$9 -> 637 | E31: ='Q2'!$E$9 -> 1854
B32: ='Q3'!$B$9 -> 997 | C32: ='Q3'!$C$9 -> 706 | D32: ='Q3'!$D$9 -> 860 | E32: ='Q3'!$E$9 -> 2563
A33: energy drinks | B33: =SUM(B30:B32) -> 1445 | C33: =SUM(C30:C32) -> 2224 | D33: =SUM(D30:D32) -> 2224 | E33: =SUM(E30:E32) -> 5893
B34: ='Q1'!$B$10 -> 211 | C34: ='Q1'!$C$10 -> 850 | D34: ='Q1'!$D$10 -> 799 | E34: ='Q1'!$E$10 -> 1860
B35: ='Q2'!$B$10 -> 936 | C35: ='Q2'!$C$10 -> 986 | D35: ='Q2'!$D$10 -> 252 | E35: ='Q2'!$E$10 -> 2174
B36: ='Q3'!$B$10 -> 621 | C36: ='Q3'!$C$10 -> 523 | D36: ='Q3'!$D$10 -> 780 | E36: ='Q3'!$E$10 -> 1924
A37: fruits juice | B37: =SUM(B34:B36) -> 1768 | C37: =SUM(C34:C36) -> 2359 | D37: =SUM(D34:D36) -> 1831 | E37: =SUM(E34:E36) -> 5958
B38: ='Q1'!$B$11 -> 3695 | C38: ='Q1'!$C$11 -> 5005 | D38: ='Q1'!$D$11 -> 4731 | E38: ='Q1'!$E$11 -> 13431
B39: ='Q2'!$B$11 -> 5700 | C39: ='Q2'!$C$11 -> 5454 | D39: ='Q2'!$D$11 -> 3853 | E39: ='Q2'!$E$11 -> 15007
B40: ='Q3'!$B$11 -> 6257 | C40: ='Q3'!$C$11 -> 3955 | D40: ='Q3'!$D$11 -> 4867 | E40: ='Q3'!$E$11 -> 15079
...

Sheet MAX
B1: jan | C1: feb | D1: mar | E1: total
B2: ='Q1'!$B$2 -> 322 | C2: ='Q1'!$C$2 -> 554 | D2: ='Q1'!$D$2 -> 299 | E2: ='Q1'!$E$2 -> 1175
B3: ='Q2'!$B$2 -> 514 | C3: ='Q2'!$C$2 -> 799 | D3: ='Q2'!$D$2 -> 394 | E3: ='Q2'!$E$2 -> 1707
B4: ='Q3'!$B$2 -> 870 | C4: ='Q3'!$C$2 -> 207 | D4: ='Q3'!$D$2 -> 117 | E4: ='Q3'!$E$2 -> 1194
A5: coffee | B5: =MAX(B2:B4) -> 870 | C5: =MAX(C2:C4) -> 799 | D5: =MAX(D2:D4) -> 394 | E5: =MAX(E2:E4) -> 1707
B6: ='Q1'!$B$3 -> 655 | C6: ='Q1'!$C$3 -> 576 | D6: ='Q1'!$D$3 -> 687 | E6: ='Q1'!$E$3 -> 1918
B7: ='Q2'!$B$3 -> 934 | C7: ='Q2'!$C$3 -> 242 | D7: ='Q2'!$D$3 -> 256 | E7: ='Q2'!$E$3 -> 1432
B8: ='Q3'!$B$3 -> 279 | C8: ='Q3'!$C$3 -> 158 | D8: ='Q3'!$D$3 -> 253 | E8: ='Q3'!$E$3 -> 690
A9: candy | B9: =MAX(B6:B8) -> 934 | C9: =MAX(C6:C8) -> 576 | D9: =MAX(D6:D8) -> 687 | E9: =MAX(E6:E8) -> 1918
B10: ='Q1'!$B$4 -> 207 | C10: ='Q1'!$C$4 -> 155 | D10: ='Q1'!$D$4 -> 152 | E10: ='Q1'!$E$4 -> 514
B11: ='Q2'!$B$4 -> 327 | C11: ='Q2'!$C$4 -> 526 | D11: ='Q2'!$D$4 -> 291 | E11: ='Q2'!$E$4 -> 1144
B12: ='Q3'!$B$4 -> 993 | C12: ='Q3'!$C$4 -> 322 | D12: ='Q3'!$D$4 -> 345 | E12: ='Q3'!$E$4 -> 1660
A13: chocalate | B13: =MAX(B10:B12) -> 993 | C13: =MAX(C10:C12) -> 526 | D13: =MAX(D10:D12) -> 345 | E13: =MAX(E10:E12) -> 1660
B14: ='Q1'!$B$5 -> 692 | C14: ='Q1'!$C$5 -> 219 | D14: ='Q1'!$D$5 -> 646 | E14: ='Q1'!$E$5 -> 1557
B15: ='Q2'!$B$5 -> 644 | C15: ='Q2'!$C$5 -> 525 | D15: ='Q2'!$D$5 -> 867 | E15: ='Q2'!$E$5 -> 2036
B16: ='Q3'!$B$5 -> 608 | C16: ='Q3'!$C$5 -> 247 | D16: ='Q3'!$D$5 -> 602 | E16: ='Q3'!$E$5 -> 1457
A17: sugar | B17: =MAX(B14:B16) -> 692 | C17: =MAX(C14:C16) -> 525 | D17: =MAX(D14:D16) -> 867 | E17: =MAX(E14:E16) -> 2036
B18: ='Q1'!$B$6 -> 207 | C18: ='Q1'!$C$6 -> 822 | D18: ='Q1'!$D$6 -> 395 | E18: ='Q1'!$E$6 -> 1424
B19: ='Q2'!$B$6 -> 975 | C19: ='Q2'!$C$6 -> 537 | D19: ='Q2'!$D$6 -> 210 | E19: ='Q2'!$E$6 -> 1722
B20: ='Q3'!$B$6 -> 690 | C20: ='Q3'!$C$6 -> 651 | D20: ='Q3'!$D$6 -> 728 | E20: ='Q3'!$E$6 -> 2069
A21: milk powder | B21: =MAX(B18:B20) -> 975 | C21: =MAX(C18:C20) -> 822 | D21: =MAX(D18:D20) -> 728 | E21: =MAX(E18:E20) -> 2069
B22: ='Q1'!$B$7 -> 759 | C22: ='Q1'!$C$7 -> 652 | D22: ='Q1'!$D$7 -> 447 | E22: ='Q1'!$E$7 -> 1858
B23: ='Q2'!$B$7 -> 306 | C23: ='Q2'!$C$7 -> 694 | D23: ='Q2'!$D$7 -> 336 | E23: ='Q2'!$E$7 -> 1336
B24: ='Q3'!$B$7 -> 670 | C24: ='Q3'!$C$7 -> 590 | D24: ='Q3'!$D$7 -> 343 | E24: ='Q3'!$E$7 -> 1603
A25: biscuits | B25: =MAX(B22:B24) -> 759 | C25: =MAX(C22:C24) -> 694 | D25: =MAX(D22:D24) -> 447 | E25: =MAX(E22:E24) -> 1858
B26: ='Q1'!$B$8 -> 447 | C26: ='Q1'!$C$8 -> 623 | D26: ='Q1'!$D$8 -> 579 | E26: ='Q1'!$E$8 -> 1649
B27: ='Q2'!$B$8 -> 811 | C27: ='Q2'!$C$8 -> 181 | D27: ='Q2'!$D$8 -> 610 | E27: ='Q2'!$E$8 -> 1602
B28: ='Q3'!$B$8 -> 529 | C28: ='Q3'!$C$8 -> 551 | D28: ='Q3'!$D$8 -> 839 | E28: ='Q3'!$E$8 -> 1919
A29: cold drinks | B29: =MAX(B26:B28) -> 811 | C29: =MAX(C26:C28) -> 623 | D29: =MAX(D26:D28) -> 839 | E29: =MAX(E26:E28) -> 1919
B30: ='Q1'!$B$9 -> 195 | C30: ='Q1'!$C$9 -> 554 | D30: ='Q1'!$D$9 -> 727 | E30: ='Q1'!$E$9 -> 1476
B31: ='Q2'!$B$9 -> 253 | C31: ='Q2'!$C$9 -> 964 | D31: ='Q2'!$D$9 -> 637 | E31: ='Q2'!$E$9 -> 1854
B32: ='Q3'!$B$9 -> 997 | C32: ='Q3'!$C$9 -> 706 | D32: ='Q3'!$D$9 -> 860 | E32: ='Q3'!$E$9 -> 2563
A33: energy drinks | B33: =MAX(B30:B32) -> 997 | C33: =MAX(C30:C32) -> 964 | D33: =MAX(D30:D32) -> 860 | E33: =MAX(E30:E32) -> 2563
B34: ='Q1'!$B$10 -> 211 | C34: ='Q1'!$C$10 -> 850 | D34: ='Q1'!$D$10 -> 799 | E34: ='Q1'!$E$10 -> 1860
B35: ='Q2'!$B$10 -> 936 | C35: ='Q2'!$C$10 -> 986 | D35: ='Q2'!$D$10 -> 252 | E35: ='Q2'!$E$10 -> 2174
B36: ='Q3'!$B$10 -> 621 | C36: ='Q3'!$C$10 -> 523 | D36: ='Q3'!$D$10 -> 780 | E36: ='Q3'!$E$10 -> 1924
A37: fruits juice | B37: =MAX(B34:B36) -> 936 | C37: =MAX(C34:C36) -> 986 | D37: =MAX(D34:D36) -> 799 | E37: =MAX(E34:E36) -> 2174
B38: ='Q1'!$B$11 -> 3695 | C38: ='Q1'!$C$11 -> 5005 | D38: ='Q1'!$D$11 -> 4731 | E38: ='Q1'!$E$11 -> 13431
B39: ='Q2'!$B$11 -> 5700 | C39: ='Q2'!$C$11 -> 5454 | D39: ='Q2'!$D$11 -> 3853 | E39: ='Q2'!$E$11 -> 15007
B40: ='Q3'!$B$11 -> 6257 | C40: ='Q3'!$C$11 -> 3955 | D40: ='Q3'!$D$11 -> 4867 | E40: ='Q3'!$E$11 -> 15079
...
